2022-Mar-19 14:10:28 | Traceback (most recent call last):
  File "/media/pythoncoder8888/ToshibaEXT/CollatzConjecture/saveCollatz.py", line 19, in <module>
    for i in tqdm(range(amount), colour="green", unit=' numbers', unit_divisor='sec', unit_scale='sec'):
  File "/home/pythoncoder8888/.local/lib/python3.8/site-packages/tqdm/std.py", line 1109, in __init__
    self.refresh(lock_args=self.lock_args)
  File "/home/pythoncoder8888/.local/lib/python3.8/site-packages/tqdm/std.py", line 1346, in refresh
    self.display()
  File "/home/pythoncoder8888/.local/lib/python3.8/site-packages/tqdm/std.py", line 1494, in display
    self.sp(self.__str__() if msg is None else msg)
  File "/home/pythoncoder8888/.local/lib/python3.8/site-packages/tqdm/std.py", line 1150, in __str__
    return self.format_meter(**self.format_dict)
  File "/home/pythoncoder8888/.local/lib/python3.8/site-packages/tqdm/std.py", line 504, in format_meter
    frac = n / total
TypeError: unsupported operand type(s) for /: 'str' and 'str'

2022-Mar-19 14:33:27 | Traceback (most recent call last):
  File "/media/pythoncoder8888/ToshibaEXT/CollatzConjecture/saveCollatz.py", line 23, in <module>
    for i in tqdm(range(amount), colour='green', unit=' numbers', postfix=f'Data file: {str(os.getcwd())}/{data_filename}', ncos=200):
  File "/home/pythoncoder8888/.local/lib/python3.8/site-packages/tqdm/std.py", line 1012, in __init__
    raise (
tqdm.std.TqdmKeyError: "Unknown argument(s): {'ncos': 200}"

2022-Mar-19 14:37:37 | Traceback (most recent call last):
  File "/media/pythoncoder8888/ToshibaEXT/CollatzConjecture/saveCollatz.py", line 20, in <module>
    amount = int(input('How many numbers do you want to calculate? '))
ValueError: invalid literal for int() with base 10: '18446744073709551616-4000'

2022-Mar-19 14:38:29 | too many iterations for tqdm progress bar, continuing without progress bar
2022-Mar-20 09:27:24 | Traceback (most recent call last):
  File "/media/pythoncoder8888/ToshibaEXT/CollatzConjecture/saveCollatz.py", line 29, in <module>
    amount = int(input('How many numbers do you want to calculate? '))
ValueError: invalid literal for int() with base 10: '999+1'

2022-Mar-20 09:33:15 | Traceback (most recent call last):
  File "/media/pythoncoder8888/ToshibaEXT/CollatzConjecture/saveCollatz.py", line 31, in <module>
    amount = int(amount)  # convert amount to integer
ValueError: invalid literal for int() with base 10: '1+3'

2022-Mar-21 10:21:00 | Traceback (most recent call last):
  File "/media/pythoncoder8888/ToshibaEXT/CollatzConjecture/saveCollatzTEST.py", line 38, in <module>
    for i in tqdm(
  File "/home/pythoncoder8888/.local/lib/python3.8/site-packages/tqdm/std.py", line 1012, in __init__
    raise (
tqdm.std.TqdmKeyError: "Unknown argument(s): {'prefix': 'Calculating:'}"

2022-Mar-21 10:24:16 | Traceback (most recent call last):
  File "/media/pythoncoder8888/ToshibaEXT/CollatzConjecture/saveCollatzTEST.py", line 38, in <module>
    for i in tqdm(
  File "/home/pythoncoder8888/.local/lib/python3.8/site-packages/tqdm/std.py", line 1012, in __init__
    raise (
tqdm.std.TqdmKeyError: "Unknown argument(s): {'prefix': 'Calculating'}"

2022-Mar-21 10:25:42 | Traceback (most recent call last):
  File "/media/pythoncoder8888/ToshibaEXT/CollatzConjecture/saveCollatzTEST.py", line 38, in <module>
    for i in tqdm(
  File "/home/pythoncoder8888/.local/lib/python3.8/site-packages/tqdm/std.py", line 1012, in __init__
    raise (
tqdm.std.TqdmKeyError: "Unknown argument(s): {'prefix': 'Calculating'}"

2022-Mar-21 10:27:16 | Traceback (most recent call last):
  File "/media/pythoncoder8888/ToshibaEXT/CollatzConjecture/saveCollatzTEST.py", line 38, in <module>
    for i in tqdm(
  File "/home/pythoncoder8888/.local/lib/python3.8/site-packages/tqdm/std.py", line 1012, in __init__
    raise (
tqdm.std.TqdmKeyError: "Unknown argument(s): {'prefix': ''}"

2022-Mar-21 10:28:12 | Traceback (most recent call last):
  File "/media/pythoncoder8888/ToshibaEXT/CollatzConjecture/saveCollatzTEST.py", line 49, in <module>
    for i in tqdm(
  File "/home/pythoncoder8888/.local/lib/python3.8/site-packages/tqdm/std.py", line 1012, in __init__
    raise (
tqdm.std.TqdmKeyError: "Unknown argument(s): {'prefix': 'Writing'}"

2022-Mar-21 11:07:14 | Traceback (most recent call last):
  File "/media/pythoncoder8888/ToshibaEXT/CollatzConjecture/saveCollatzTEST.py", line 55, in <module>
    data_file.write(str(data_list[i]) + '\n')
OSError: [Errno 27] File too large

2022-Mar-21 11:12:20 | Traceback (most recent call last):
  File "/media/pythoncoder8888/ToshibaEXT/CollatzConjecture/saveCollatzTEST.py", line 55, in <module>
    data_file.write(str(data_list[i]) + '\n')
OSError: [Errno 27] File too large

2022-Mar-21 15:31:43 | Traceback (most recent call last):
  File "/media/pythoncoder8888/ToshibaEXT/CollatzConjecture/saveCollatzTEST.py", line 55, in <module>
    data_file.write(str(data_list[i]) + '\n')
OSError: [Errno 27] File too large

2022-Mar-21 18:57:32 | Traceback (most recent call last):
  File "/media/pythoncoder8888/ToshibaEXT/CollatzConjecture/saveCollatzTEST.py", line 38, in <module>
    data_file = open(data_filename, 'r')
FileNotFoundError: [Errno 2] No such file or directory: 'collatz_1-999999.txt'

2022-Mar-21 19:08:48 | Traceback (most recent call last):
  File "/media/pythoncoder8888/ToshibaEXT/CollatzConjecture/saveCollatzTEST.py", line 38, in <module>
    data_file = open(data_filename, 'r')
FileNotFoundError: [Errno 2] No such file or directory: 'collatz_1-999999.txt'

2022-Mar-21 19:12:40 | Traceback (most recent call last):
  File "/media/pythoncoder8888/ToshibaEXT/CollatzConjecture/saveCollatzTEST.py", line 39, in <module>
    data_file = open(data_filename, 'r')
FileNotFoundError: [Errno 2] No such file or directory: 'collatz_1-999999.txt'

2022-Mar-21 19:13:20 | Traceback (most recent call last):
  File "/media/pythoncoder8888/ToshibaEXT/CollatzConjecture/saveCollatzTEST.py", line 39, in <module>
    data_file = open(data_filename.replace("'",""), 'r')
FileNotFoundError: [Errno 2] No such file or directory: 'collatz_1-999999.txt'

2022-Mar-21 19:14:36 | Traceback (most recent call last):
  File "/media/pythoncoder8888/ToshibaEXT/CollatzConjecture/saveCollatzTEST.py", line 39, in <module>
    data_file = open(os.getcwd() + 'data' + data_filename, 'r')
FileNotFoundError: [Errno 2] No such file or directory: '/media/pythoncoder8888/ToshibaEXT/CollatzConjecturedatacollatz_1-999999.txt'

2022-Mar-21 19:19:12 | Traceback (most recent call last):
  File "/media/pythoncoder8888/ToshibaEXT/CollatzConjecture/saveCollatzTEST.py", line 114, in <module>
    data_filename=f'collatz_{lastfilename+(1000000*i)}-{lastfilename+i+1}999999'
TypeError: can only concatenate str (not "int") to str

2022-Mar-21 19:21:23 | Traceback (most recent call last):
  File "/media/pythoncoder8888/ToshibaEXT/CollatzConjecture/saveCollatzTEST.py", line 112, in <module>
    write_and_compute(
  File "/media/pythoncoder8888/ToshibaEXT/CollatzConjecture/saveCollatzTEST.py", line 64, in write_and_compute
    data_list.append(data)
NameError: name 'data_list' is not defined

2022-Mar-21 19:22:25 | Traceback (most recent call last):
  File "/media/pythoncoder8888/ToshibaEXT/CollatzConjecture/saveCollatzTEST.py", line 119, in <module>
    del data_list
NameError: name 'data_list' is not defined

2022-Mar-21 20:41:13 | Traceback (most recent call last):
  File "/media/pythoncoder8888/ToshibaEXT/CollatzConjecture/saveCollatzTEST.py", line 102, in <module>
    write_and_compute(
  File "/media/pythoncoder8888/ToshibaEXT/CollatzConjecture/saveCollatzTEST.py", line 68, in write_and_compute
    data_file = open(data_filename, 'a')
FileNotFoundError: [Errno 2] No such file or directory: '/data/collatz_1-999999.txt'

2022-Mar-21 20:43:02 | Traceback (most recent call last):
  File "/media/pythoncoder8888/ToshibaEXT/CollatzConjecture/saveCollatzTEST.py", line 121, in <module>
    data_filename=f'collatz_{int(lastfilename)+int((1000000*i))}-{int(lastfilename)+int(i)}999999'
ValueError: invalid literal for int() with base 10: '-'

2022-Mar-22 17:35:40 | Traceback (most recent call last):
  File "/media/pythoncoder8888/ToshibaEXT/CollatzConjecture/saveCollatzTEST.py", line 114, in <module>
    write_and_compute(
  File "/media/pythoncoder8888/ToshibaEXT/CollatzConjecture/saveCollatzTEST.py", line 68, in write_and_compute
    data_file = open(data_filename, 'a')
FileNotFoundError: [Errno 2] No such file or directory: '/data/collatz_27000001-54000000'

2022-Mar-22 17:37:56 | Traceback (most recent call last):
  File "/media/pythoncoder8888/ToshibaEXT/CollatzConjecture/saveCollatzTEST.py", line 114, in <module>
    write_and_compute(
  File "/media/pythoncoder8888/ToshibaEXT/CollatzConjecture/saveCollatzTEST.py", line 68, in write_and_compute
    data_file = open(data_filename, 'a')
FileNotFoundError: [Errno 2] No such file or directory: '/data/collatz_1000001-2000000'

2022-Mar-22 17:41:05 | Traceback (most recent call last):
  File "/media/pythoncoder8888/ToshibaEXT/CollatzConjecture/saveCollatzTEST.py", line 69, in write_and_compute
    data_file = open(data_filename, 'a')
FileNotFoundError: [Errno 2] No such file or directory: '/data/collatz_1000001-2000000'

During handling of the above exception, another exception occurred:

Traceback (most recent call last):
  File "/media/pythoncoder8888/ToshibaEXT/CollatzConjecture/saveCollatzTEST.py", line 124, in <module>
    write_and_compute(
  File "/media/pythoncoder8888/ToshibaEXT/CollatzConjecture/saveCollatzTEST.py", line 71, in write_and_compute
    data_file = open(data_filename, 'w')
FileNotFoundError: [Errno 2] No such file or directory: '/data/collatz_1000001-2000000'

2022-Mar-22 17:43:07 | Traceback (most recent call last):
  File "/media/pythoncoder8888/ToshibaEXT/CollatzConjecture/saveCollatzTEST.py", line 69, in write_and_compute
    data_file = open(data_filename, 'a')
FileNotFoundError: [Errno 2] No such file or directory: '/data/collatz_1000001-2000000'

During handling of the above exception, another exception occurred:

Traceback (most recent call last):
  File "/media/pythoncoder8888/ToshibaEXT/CollatzConjecture/saveCollatzTEST.py", line 124, in <module>
    write_and_compute(
  File "/media/pythoncoder8888/ToshibaEXT/CollatzConjecture/saveCollatzTEST.py", line 71, in write_and_compute
    data_file = open(data_filename, 'x')
FileNotFoundError: [Errno 2] No such file or directory: '/data/collatz_1000001-2000000'

2022-Mar-22 17:44:22 | Traceback (most recent call last):
  File "/media/pythoncoder8888/ToshibaEXT/CollatzConjecture/saveCollatzTEST.py", line 114, in <module>
    write_and_compute(
  File "/media/pythoncoder8888/ToshibaEXT/CollatzConjecture/saveCollatzTEST.py", line 68, in write_and_compute
    data_file = open(data_filename, 'a')
FileNotFoundError: [Errno 2] No such file or directory: '/data/collatz_1000001-2000000.txt'

2022-Mar-22 17:48:52 | Traceback (most recent call last):
  File "/media/pythoncoder8888/ToshibaEXT/CollatzConjecture/saveCollatzTEST.py", line 115, in <module>
    newfile = open(newfilename)
FileNotFoundError: [Errno 2] No such file or directory: '/data/collatz_1000001-2000000.txt'

2022-Mar-22 17:49:58 | Traceback (most recent call last):
  File "/media/pythoncoder8888/ToshibaEXT/CollatzConjecture/saveCollatzTEST.py", line 115, in <module>
    newfile = open(newfilename)
FileNotFoundError: [Errno 2] No such file or directory: 'collatz_1000001-2000000.txt'

2022-Mar-22 18:50:19 | Traceback (most recent call last):
  File "/media/pythoncoder8888/ToshibaEXT/CollatzConjecture/saveCollatzTEST.py", line 115, in <module>
    newfile = open(newfilename, 'x')
FileNotFoundError: [Errno 2] No such file or directory: '/data/collatz_1000001-2000000.txt'

2022-Mar-22 18:59:44 | Traceback (most recent call last):
  File "/media/pythoncoder8888/ToshibaEXT/CollatzConjecture/saveCollatzTEST.py", line 42, in <module>
    file_data = file_data[-1]  # choose last line from file
IndexError: list index out of range

2022-Mar-22 19:01:30 | Traceback (most recent call last):
  File "/media/pythoncoder8888/ToshibaEXT/CollatzConjecture/saveCollatzTEST.py", line 42, in <module>
    file_data = file_data[-1]  # choose last line from file
IndexError: list index out of range

2022-Mar-22 19:03:40 | Traceback (most recent call last):
  File "/media/pythoncoder8888/ToshibaEXT/CollatzConjecture/saveCollatzTEST.py", line 115, in <module>
    newfile = open(newfilename, 'x')
FileNotFoundError: [Errno 2] No such file or directory: '/media/pythoncoder8888/ToshibaEXT/CollatzConjecturedata/collatz_100001-200000.txt'

2022-Mar-22 19:19:46 | Traceback (most recent call last):
  File "/media/pythoncoder8888/ToshibaEXT/CollatzConjecture/saveCollatzTEST.py", line 116, in <module>
    newfile = open(newfilename, 'x')
FileNotFoundError: [Errno 2] No such file or directory: '/media/pythoncoder8888/ToshibaEXT/CollatzConjecturedata/collatz_100001-200000.txt'

2022-Mar-23 16:48:25 | Traceback (most recent call last):
  File "/media/pythoncoder8888/ToshibaEXT/CollatzConjecture/saveCollatzTEST.py", line 103, in <module>
    amount_left = total - num_lines_left_prev_file
NameError: name 'total' is not defined

2022-Mar-23 16:49:22 | Traceback (most recent call last):
  File "/media/pythoncoder8888/ToshibaEXT/CollatzConjecture/saveCollatzTEST.py", line 117, in <module>
    data_to_files = [total]
NameError: name 'total' is not defined

2022-Mar-23 16:51:51 | Traceback (most recent call last):
  File "/media/pythoncoder8888/ToshibaEXT/CollatzConjecture/saveCollatzTEST.py", line 131, in <module>
    dash_index = lastfilename.index('-')
ValueError: '-' is not in list

2022-Mar-23 16:52:41 | Traceback (most recent call last):
  File "/media/pythoncoder8888/ToshibaEXT/CollatzConjecture/saveCollatzTEST.py", line 132, in <module>
    newfilename = f'{os.getcwd()}/data/collatz_{str(value_index + lastfilename[dash_index+1])}{str(power / 10)}1-{str(value_index + lastfilename[dash_index+1])}{str(power / 10)}.txt'
IndexError: list index out of range

2022-Mar-23 16:54:33 | Traceback (most recent call last):
  File "/media/pythoncoder8888/ToshibaEXT/CollatzConjecture/saveCollatzTEST.py", line 134, in <module>
    newfilename = f'{os.getcwd()}/data/collatz_{str(value_index + lastfilename[dash_index+1])}{str(power / 10)}1-{str(value_index + lastfilename[dash_index+1])}{str(power / 10)}.txt'
IndexError: list index out of range

2022-Mar-23 16:55:23 | Traceback (most recent call last):
  File "/media/pythoncoder8888/ToshibaEXT/CollatzConjecture/saveCollatzTEST.py", line 132, in <module>
    newfilename = f'{os.getcwd()}/data/collatz_{str(value_index + lastfilename[-1][dash_index+1])}{str(power / 10)}1-{str(value_index + lastfilename[-1][dash_index+1])}{str(power / 10)}.txt'
TypeError: unsupported operand type(s) for +: 'int' and 'str'

2022-Mar-23 16:57:01 | Traceback (most recent call last):
  File "/media/pythoncoder8888/ToshibaEXT/CollatzConjecture/saveCollatzTEST.py", line 135, in <module>
    write_and_compute(
  File "/media/pythoncoder8888/ToshibaEXT/CollatzConjecture/saveCollatzTEST.py", line 69, in write_and_compute
    data_file = open(data_filename, 'a')
FileNotFoundError: [Errno 2] No such file or directory: '/media/pythoncoder8888/ToshibaEXT/CollatzConjecture/data//media/pythoncoder8888/ToshibaEXT/CollatzConjecture/data/collatz_0110000.01-0110000.0.txt'

2022-Mar-23 16:58:04 | Traceback (most recent call last):
  File "/media/pythoncoder8888/ToshibaEXT/CollatzConjecture/saveCollatzTEST.py", line 43, in <module>
    file_data = file_data[-1]  # choose last line from file
IndexError: list index out of range

2022-Mar-23 17:00:57 | Traceback (most recent call last):
  File "/media/pythoncoder8888/ToshibaEXT/CollatzConjecture/saveCollatzTEST.py", line 135, in <module>
    write_and_compute(
  File "/media/pythoncoder8888/ToshibaEXT/CollatzConjecture/saveCollatzTEST.py", line 69, in write_and_compute
    data_file = open(data_filename, 'a')
FileNotFoundError: [Errno 2] No such file or directory: '/media/pythoncoder8888/ToshibaEXT/CollatzConjecture/data//media/pythoncoder8888/ToshibaEXT/CollatzConjecture/data/collatz_0110000.01-0110000.0.txt'

2022-Mar-23 17:02:42 | Traceback (most recent call last):
  File "/media/pythoncoder8888/ToshibaEXT/CollatzConjecture/saveCollatzTEST.py", line 43, in <module>
    file_data = file_data[-1]  # choose last line from file
IndexError: list index out of range

2022-Mar-23 18:56:25 | Traceback (most recent call last):
  File "/media/pythoncoder8888/ToshibaEXT/CollatzConjecture/saveCollatzTEST.py", line 134, in <module>
    newfile = open(newfilename, 'x')
FileExistsError: [Errno 17] File exists: '/media/pythoncoder8888/ToshibaEXT/CollatzConjecture/data/collatz_1001-2000.txt'

2022-Mar-23 19:03:58 | Traceback (most recent call last):
  File "/media/pythoncoder8888/ToshibaEXT/CollatzConjecture/saveCollatzTEST.py", line 136, in <module>
    newfile = open(newfilename, 'x')
FileExistsError: [Errno 17] File exists: '/media/pythoncoder8888/ToshibaEXT/CollatzConjecture/data/collatz_1001-2000.txt'

2022-Mar-23 19:59:14 | Traceback (most recent call last):
  File "/media/pythoncoder8888/ToshibaEXT/CollatzConjecture/saveCollatzTEST.py", line 139, in <module>
    newfile = open(newfilename, 'x')
FileExistsError: [Errno 17] File exists: '/media/pythoncoder8888/ToshibaEXT/CollatzConjecture/data/collatz_1000001-2000000.txt'

2022-Mar-23 20:54:59 | Traceback (most recent call last):
  File "/media/pythoncoder8888/ToshibaEXT/CollatzConjecture/saveCollatzTEST.py", line 142, in <module>
    newfile = open(newfilename, 'x')
FileExistsError: [Errno 17] File exists: '/media/pythoncoder8888/ToshibaEXT/CollatzConjecture/data/collatz_1000001-2000000.txt'

2022-Mar-23 20:55:48 | Traceback (most recent call last):
  File "/media/pythoncoder8888/ToshibaEXT/CollatzConjecture/saveCollatzTEST.py", line 142, in <module>
    newfile = open(newfilename, 'x')
FileExistsError: [Errno 17] File exists: '/media/pythoncoder8888/ToshibaEXT/CollatzConjecture/data/collatz_1000001-2000000.txt'

2022-Mar-24 16:37:26 | Traceback (most recent call last):
  File "/media/pythoncoder8888/ToshibaEXT/CollatzConjecture/saveCollatzTEST.py", line 143, in <module>
    newfile = open(newfilename, 'x')
FileExistsError: [Errno 17] File exists: '/media/pythoncoder8888/ToshibaEXT/CollatzConjecture/data/collatz_1000001-2000000.txt'

2022-Mar-24 16:50:52 | Traceback (most recent call last):
  File "/media/pythoncoder8888/ToshibaEXT/CollatzConjecture/saveCollatzTEST.py", line 139, in <module>
    formatted_dash_index = formatted_last_file[-1].index('-')
ValueError: substring not found

2022-Mar-25 16:25:57 | Traceback (most recent call last):
  File "/media/pythoncoder8888/ToshibaEXT/CollatzConjecture/saveCollatz.py", line 47, in <module>
    file_data = file_data[-1]  # choose last line from file
IndexError: list index out of range

2022-Mar-25 16:39:29 | Traceback (most recent call last):
  File "/media/pythoncoder8888/ToshibaEXT/CollatzConjecture/saveCollatzTEST.py", line 152, in <module>
    newfile = open(newfilename, 'x')
FileExistsError: [Errno 17] File exists: '/media/pythoncoder8888/ToshibaEXT/CollatzConjecture/data/collatz_1001-2000.txt'

2022-Mar-25 16:42:13 | Traceback (most recent call last):
  File "/media/pythoncoder8888/ToshibaEXT/CollatzConjecture/saveCollatzTEST.py", line 152, in <module>
    newfile = open(newfilename, 'x')
FileExistsError: [Errno 17] File exists: '/media/pythoncoder8888/ToshibaEXT/CollatzConjecture/data/collatz_1001-2000.txt'

